<?xml version="1.0"?>
<robot xmlns:xacro="http://ros.org/wiki/xacro">

  <!-- <xacro:include filename="$(find viperX300_description)/urdf/vx300s_transmission.xacro" /> -->
  <xacro:include filename="$(find viperX300_description)/urdf/vx300s_gazebo.xacro" />

  <material name="interbotix_black">
    <texture filename="file://$(find viperX300_description)/meshes/interbotix_black.png" />
  </material>

  <xacro:macro name="vx300s" params="prefix hw_interface">
    <xacro:include filename="$(find viperX300_description)/urdf/vx300s_control.xacro" />
    <xacro:vx300s_gazebo prefix="${prefix}_" />

    <xacro:property name="pi_offset" value="0.00001" />

    <link name="${prefix}_base_link">
      <visual>
        <origin rpy="0 0 ${pi/2}" xyz="0 0 0" />
        <geometry>
          <mesh
            filename="file://$(find viperX300_description)/meshes/vx300s_1_base.stl"
            scale="0.001 0.001 0.001" />
        </geometry>
        <material name="interbotix_black" />
      </visual>
      <collision>
        <origin rpy="0 0 ${pi/2}" xyz="0 0 0" />
        <geometry>
          <mesh
            filename="file://$(find viperX300_description)/meshes/vx300s_1_base.stl"
            scale="0.001 0.001 0.001" />
        </geometry>
      </collision>
      <inertial>
        <origin rpy="0 0 ${pi/2}" xyz="-0.0534774000 -0.0005625750 0.0205961000" />
        <mass value="0.969034" />
        <inertia ixx="0.0060240000" iyy="0.0017000000" izz="0.0071620000" ixy="0.0000471300"
          ixz="0.0000038510" iyz="-0.0000841500" />
      </inertial>
    </link>

    <joint name="${prefix}_waist" type="revolute">
      <axis xyz="0 0 1" />
      <limit effort="10" lower="${-pi + pi_offset}" upper="${pi - pi_offset}" velocity="${2*pi}" />
      <origin rpy="0 0 0" xyz="0 0 0.079" />
      <parent link="${prefix}_base_link" />
      <child link="${prefix}_shoulder_link" />
      <!--dynamics friction="0.1" /-->
      <dynamics damping="0.1" friction="0.1"/>
    </joint>

    <link name="${prefix}_shoulder_link">
      <visual>
        <origin rpy="0 0 ${pi/2}" xyz="0 0 -0.003" />
        <geometry>
          <mesh
            filename="file://$(find viperX300_description)/meshes/vx300s_2_shoulder.stl"
            scale="0.001 0.001 0.001" />
        </geometry>
        <material name="interbotix_black" />
      </visual>
      <collision>
        <origin rpy="0 0 ${pi/2}" xyz="0 0 -0.003" />
        <geometry>
          <mesh
            filename="file://$(find viperX300_description)/meshes/vx300s_2_shoulder.stl"
            scale="0.001 0.001 0.001" />
        </geometry>
      </collision>
      <inertial>
        <origin rpy="0 0 ${pi/2}" xyz="0.0002592330 -0.0000033552 0.0116129000" />
        <mass value="0.798614" />
        <inertia ixx="0.0009388000" iyy="0.0011380000" izz="0.0012010000" ixy="-0.0000000010"
          ixz="-0.0000000191" iyz="0.0000059568" />
      </inertial>
    </link>

    <joint name="${prefix}_shoulder" type="revolute">
      <axis xyz="0 1 0" />
      <limit effort="20" lower="${radians(-106)}" upper="${radians(72)}" velocity="${2*pi}" />
      <origin rpy="0 0 0" xyz="0 0 0.04805" />
      <parent link="${prefix}_shoulder_link" />
      <child link="${prefix}_upper_arm_link" />
      <!--dynamics friction="0.1" /-->
      <dynamics damping="0.1" friction="0.1"/>
    </joint>

    <link name="${prefix}_upper_arm_link">
      <visual>
        <origin rpy="0 0 ${pi/2}" xyz="0 0 0" />
        <geometry>
          <mesh
            filename="file://$(find viperX300_description)/meshes/vx300s_3_upper_arm.stl"
            scale="0.001 0.001 0.001" />
        </geometry>
        <material name="interbotix_black" />
      </visual>
      <collision>
        <origin rpy="0 0 ${pi/2}" xyz="0 0 0" />
        <geometry>
          <mesh
            filename="file://$(find viperX300_description)/meshes/vx300s_3_upper_arm.stl"
            scale="0.001 0.001 0.001" />
        </geometry>
      </collision>
      <inertial>
        <origin rpy="0 0 ${pi/2}" xyz="0.0206949000 0.0000000004 0.2264590000" />
        <mass value="0.792592" />
        <inertia ixx="0.0089250000" iyy="0.0089370000" izz="0.0009357000" ixy="0.0000000000"
          ixz="0.0000000000" iyz="0.0012010000" />
      </inertial>
    </link>

    <joint name="${prefix}_elbow" type="revolute">
      <axis xyz="0 1 0" />
      <limit effort="15" lower="${radians(-101)}" upper="${radians(92)}" velocity="${2*pi}" />
      <origin rpy="0 0 0" xyz="0.05955 0 0.3" />
      <parent link="${prefix}_upper_arm_link" />
      <child link="${prefix}_upper_forearm_link" />
      <!--dynamics friction="0.1" /-->
      <dynamics damping="0.1" friction="0.1"/>
    </joint>

    <link name="${prefix}_upper_forearm_link">
      <visual>
        <origin rpy="0 0 0" xyz="0 0 0" />
        <geometry>
          <mesh
            filename="file://$(find viperX300_description)/meshes/vx300s_4_upper_forearm.stl"
            scale="0.001 0.001 0.001" />
        </geometry>
        <material name="interbotix_black" />
      </visual>
      <collision>
        <origin rpy="0 0 0" xyz="0 0 0" />
        <geometry>
          <mesh
            filename="file://$(find viperX300_description)/meshes/vx300s_4_upper_forearm.stl"
            scale="0.001 0.001 0.001" />
        </geometry>
      </collision>
      <inertial>
        <origin rpy="0 0 0" xyz="0.105723 0 0" />
        <mass value="0.322228" />
        <inertia ixx="0.0001524000" iyy="0.0013420000" izz="0.0014410000" ixy="-0.0000188300"
          ixz="-0.0000084064" iyz="0.0000012564" />
      </inertial>
    </link>

    <joint name="${prefix}_forearm_roll" type="revolute">
      <axis xyz="1 0 0" />
      <limit effort="2" lower="${-pi + pi_offset}" upper="${pi - pi_offset}" velocity="${2*pi}" />
      <origin rpy="0 0 0" xyz="0.2 0 0" />
      <parent link="${prefix}_upper_forearm_link" />
      <child link="${prefix}_lower_forearm_link" />
      <!--dynamics friction="0.1" /-->
      <dynamics damping="0.1" friction="0.1"/>
    </joint>

    <link name="${prefix}_lower_forearm_link">
      <visual>
        <origin rpy="${pi} 0 0" xyz="0 0 0" />
        <geometry>
          <mesh
            filename="file://$(find viperX300_description)/meshes/vx300s_5_lower_forearm.stl"
            scale="0.001 0.001 0.001" />
        </geometry>
        <material name="interbotix_black" />
      </visual>
      <collision>
        <origin rpy="${pi} 0 0" xyz="0 0 0" />
        <geometry>
          <mesh
            filename="file://$(find viperX300_description)/meshes/vx300s_5_lower_forearm.stl"
            scale="0.001 0.001 0.001" />
        </geometry>
      </collision>
      <inertial>
        <origin rpy="${pi} 0 0" xyz="0.0513477000 0.0068046200 0" />
        <mass value="0.414823" />
        <inertia ixx="0.0001753000" iyy="0.0005269000" izz="0.0005911000" ixy="-0.0000852800"
          ixz="0" iyz="0" />
      </inertial>
    </link>
    
    
    <joint name="${prefix}_wrist_angle" type="revolute">
      <axis xyz="0 1 0" />
      <limit effort="5" lower="${radians(-107)}" upper="${radians(128)}" velocity="${2*pi}" />
      <origin rpy="0 0 0" xyz="0.1 0 0" />
      <parent link="${prefix}_lower_forearm_link" />
      <child link="${prefix}_wrist_link" />
      <dynamics damping="0.1" friction="0.1"/>
    </joint>

    <link name="${prefix}_wrist_link">
      <visual>
        <origin rpy="0 0 ${pi/2}" xyz="0 0 0" />
        <geometry>
          <mesh
            filename="file://$(find viperX300_description)/meshes/vx300s_6_wrist.stl"
            scale="0.001 0.001 0.001" />
        </geometry>
        <material name="interbotix_black" />
      </visual>
      <collision>
        <origin rpy="0 0 ${pi/2}" xyz="0 0 0" />
        <geometry>
          <mesh
            filename="file://$(find viperX300_description)/meshes/vx300s_6_wrist.stl"
            scale="0.001 0.001 0.001" />
        </geometry>
      </collision>
      <inertial>
        <origin rpy="0 0 ${pi/2}" xyz="0.0467430000 -0.0000076652 0.0105650000" />
        <mass value="0.115395" />
        <inertia ixx="0.0000463100" iyy="0.0000451400" izz="0.0000527000" ixy="0.0000000195"
          ixz="0.0000000023" iyz="0.0000042002" />
      </inertial>
    </link>
    

    <joint name="${prefix}_wrist_rotate" type="revolute">
      <axis xyz="1 0 0" />
      <limit effort="1" lower="${-pi/2 + pi_offset}" upper="${pi/2 - pi_offset}" velocity="${2*pi}" />
      <origin rpy="0 0 0" xyz="0.069744 0 0" />
      <parent link="${prefix}_wrist_link" />
      <child link="${prefix}_gripper_link" />
      <dynamics damping="0.1" friction="0.1"/>
    </joint>

    <link name="${prefix}_gripper_link">
      <visual>
        <origin rpy="0 0 ${pi/2}" xyz="-0.02 0 0" />
        <geometry>
          <mesh
            filename="file://$(find viperX300_description)/meshes/vx300s_7_gripper.stl"
            scale="0.001 0.001 0.001" />
        </geometry>
        <material name="interbotix_black" />
      </visual>
      <collision>
        <origin rpy="0 0 ${pi/2}" xyz="-0.02 0 0" />
        <geometry>
          <mesh
            filename="file://$(find viperX300_description)/meshes/vx300s_7_gripper.stl"
            scale="0.001 0.001 0.001" />
        </geometry>
      </collision>
      <inertial>
        <origin rpy="0 0 ${pi/2}" xyz="0.0230010000 0.0000000000 0.0115230000" />
        <mass value="0.097666" />
        <inertia ixx="0.0000326800" iyy="0.0000243600" izz="0.0000211900" ixy="0.0000000000"
          ixz="0.0000000000" iyz="0.0000002785" />
      </inertial>
    </link>

    <!--joint name="${prefix}_ee_arm" type="fixed">
      <axis xyz="1 0 0" />
      <origin rpy="0 0 0" xyz="0.042825 0 0" />
      <parent link="${prefix}_gripper_link" />
      <child link="${prefix}_ee_arm_link" />
    </joint-->

    <!--link name="${prefix}_ee_arm_link">
      <inertial>
        <mass value="0.001" />
        <inertia ixx="0.0001" iyy="0.0001" izz="0.0001" ixy="0" ixz="0" iyz="0" />
      </inertial>
    </link-->


    <joint name="${prefix}_gripper_bar" type="fixed">
      <axis xyz="1 0 0" />
      <origin rpy="0 0 0" xyz="0.05 0 0" />
      <parent link="${prefix}_gripper_link" />
      <child link="${prefix}_gripper_bar_link" />
    </joint>

    <link name="${prefix}_gripper_bar_link">
      <visual>
        <origin rpy="0 0 ${pi/2}" xyz="-0.063 0 0" />
        <geometry>
          <mesh
            filename="file://$(find viperX300_description)/meshes/vx300s_9_gripper_bar.stl"
            scale="0.001 0.001 0.001" />
        </geometry>
        <material name="interbotix_black" />
      </visual>
      <collision>
        <origin rpy="0 0 ${pi/2}" xyz="-0.063 0 0" />
        <geometry>
          <mesh
            filename="file://$(find viperX300_description)/meshes/vx300s_9_gripper_bar.stl"
            scale="0.001 0.001 0.001" />
        </geometry>
      </collision>
      <inertial>
        <origin rpy="0 0 ${pi/2}" xyz="0.0067940000 -0.0000004272 -0.0007760000" />
        <mass value="0.150986" />
        <inertia ixx="0.0000789500" iyy="0.0003283000" izz="0.0003095000" ixy="-0.0000000012"
          ixz="0.0000001341" iyz="0.0000017465" />
      </inertial>
    </link>

    <joint name="${prefix}_ee_bar" type="fixed">
      <axis xyz="1 0 0" />
      <origin rpy="0 0 0" xyz="0.025875 0 0" />
      <parent link="${prefix}_gripper_bar_link" />
      <child link="${prefix}_fingers_link" />
    </joint>
    

    <link name="${prefix}_fingers_link">
      <inertial>
        <mass value="0.001" />
        <inertia ixx="0.0001" iyy="0.0001" izz="0.0001" ixy="0" ixz="0" iyz="0" />
      </inertial>
    </link>

    <joint name="${prefix}_left_finger" type="prismatic">
      <axis xyz="0 1 0" />
      <limit effort="50" lower="0.021" upper="0.057" velocity="2.5" />
      <origin rpy="0 0 0" xyz="0 0 0" />
      <parent link="${prefix}_fingers_link" />
      <child link="${prefix}_left_finger_link" />
      <dynamics damping="0.1" friction="0.1"/>

    </joint>

    <link name="${prefix}_left_finger_link">
      <visual>
        <origin rpy="${pi/2} ${-pi} ${pi/2}" xyz="-0.0404 -0.0575 0" />
        <geometry>
          <mesh
            filename="file://$(find viperX300_description)/meshes/vx300s_10_gripper_finger.stl"
            scale="0.001 0.001 0.001" />
        </geometry>
        <material name="interbotix_black" />
      </visual>
      <collision>
        <origin rpy="${pi/2} ${-pi} ${pi/2}" xyz="-0.0404 -0.0575 0" />
        <geometry>
          <mesh
            filename="file://$(find viperX300_description)/meshes/vx300s_10_gripper_finger.stl"
            scale="0.001 0.001 0.001" />
        </geometry>
      </collision>
      <inertial>
        <origin rpy="${pi} ${pi} ${pi/2}" xyz="0.0173440000 -0.0060692000 0.0000000000" />
        <mass value="0.034796" />
        <inertia ixx="0.0000243300" iyy="0.0000125500" izz="0.0000141700" ixy="-0.0000024004"
          ixz="0.0000000000" iyz="0.0000000000" />
      </inertial>
    </link>

    <joint name="${prefix}_right_finger" type="prismatic">
      <axis xyz="0 1 0" />
      <limit effort="50" lower="-0.057" upper="-0.021" velocity="2.5" />
      <origin rpy="0 0 0" xyz="0 0 0" />
      <parent link="${prefix}_fingers_link" />
      <child link="${prefix}_right_finger_link" />
      <dynamics damping="0.1" friction="0.1"/>
    </joint>

    <link name="${prefix}_right_finger_link">
      <visual>
        <origin rpy="${-pi/2} ${pi} ${-pi/2}" xyz="-0.0404 0.0575 0 " />
        <geometry>
          <mesh
            filename="file://$(find viperX300_description)/meshes/vx300s_10_gripper_finger.stl"
            scale="0.001 0.001 0.001" />
        </geometry>
        <material name="interbotix_black" />
      </visual>
      <collision>
        <origin rpy="${-pi/2} ${pi} ${-pi/2}" xyz="-0.0404 0.0575 0 " />
        <geometry>
          <mesh
            filename="file://$(find viperX300_description)/meshes/vx300s_10_gripper_finger.stl"
            scale="0.001 0.001 0.001" />
        </geometry>
      </collision>
      <inertial>
        <origin rpy="0 ${pi} ${pi/2}" xyz="0.0173440000 0.0060692000  0.0000000000" />
        <mass value="0.034796" />
        <inertia ixx="0.0000243300" iyy="0.0000125500" izz="0.0000141700" ixy="0.0000024001"
          ixz="0.0000000000" iyz="0.0000000000" />
      </inertial>
    </link>

    <!--joint name="${prefix}_ee_gripper" type="fixed">
      <axis xyz="1 0 0" />
      <origin rpy="0 0 0" xyz="0.0385 0 0" />
      <parent link="${prefix}_fingers_link" />
      <child link="${prefix}_ee_gripper_link" />
    </joint>

 
    <link name="${prefix}_ee_gripper_link">
      <inertial>
        <mass value="0.001" />
        <inertia ixx="0.0001" iyy="0.0001" izz="0.0001" ixy="0" ixz="0" iyz="0" />
      </inertial>
    </link-->
    
        <!-- Dummy camera link -->
<link name="${prefix}_CAM_1">
  <visual>
    <geometry>
      <box size="0.05 0.05 0.05"/>
    </geometry>
    <material name="interbotix_black" />
  </visual>
  <collision>
    <geometry>
      <box size="0.05 0.05 0.05"/>
    </geometry>
  </collision>
  <inertial>
    <mass value="0.1"/>
    <inertia ixx="0.0001" ixy="0.0" ixz="0.0"
             iyy="0.0001" iyz="0.0"
             izz="0.0001"/>
  </inertial>
</link>

<!-- Joint connecting camera to base_link -->
<joint name="${prefix}_CAM_joint" type="fixed">
  <parent link="${prefix}_gripper_bar_link"/>
  <child link="${prefix}_CAM_1"/>
  <origin xyz="-0.025 0.0 0.09" rpy="0.0 0.45 0"/>
</joint>
    
    <gazebo reference="${prefix}_CAM_1">
  <sensor name="${prefix}_zed_CAM" type="camera">
    <always_on>true</always_on>
    <update_rate>30</update_rate>
    <!--pose>0.05 0 0 0 0 0.15</pose-->
    <visualize>true</visualize>
    <topic>/${prefix}_cam_arm/image_raw</topic>
    <gz_frame_id>${prefix}_CAM_1</gz_frame_id>
    <camera name="${prefix}_zed_CAM">
      <horizontal_fov>1.047</horizontal_fov>
      <camera_info_topic>/${prefix}_cam_arm/camera_info</camera_info_topic>
      <distortion>
        <k1>0.01</k1>
        <k2>0.01</k2>
        <k3>0.01</k3>
        <p1>0.001</p1>
        <p2>0.001</p2>
      </distortion>
      <image>
        <width>224</width>
        <height>224</height>
        <format>R8G8B8</format>
      </image>
      <clip>
        <near>0.01</near>
        <far>5.0</far>
      </clip>
      <noise>
        <type>gaussian</type>
        <mean>0.01</mean>
        <stddev>0.005</stddev>
      </noise>
       <!--depth_camera>
        <clip>
          <near>0.01</near>
          <far>5</far>
        </clip>
      </depth_camera-->
    </camera>
  </sensor>
</gazebo>

  </xacro:macro>
</robot>
